Workbook

Sheet بيانات المنشأة و تردد العيادات
A1: 📋 بيانات المنشأة الصحية و تردد العيادات
A3: اسم المنشأة | B3: وحدة غ
A4: كود المنشأة | B4: ASU-BDR-001
A5: نوع المنشأة
A6: الادارة الصحية
A7: المديرية
A8: العنوان
A9: اجمالي عدد المواطنين
A10: عدد العيادات
A11: اجمالي عدد العاملين
A12: عدد الاطباء واطباء الاسنان
A13: عدد التمريض
A14: عدد الصيادلة
A15: عدد الفئات الاخرى
A17: تخصصات العيادات | B17: تردد العيادة الشهري | C17: 46023 | D17: 46054 | E17: 46082 | F17: 46113 | G17: 46143 | H17: 46174 | I17: 46204 | J17: 46235 | K17: 46266 | L17: 46296 | M17: 46327 | N17: 46357
B18: طب الأسرة | H18: 230
B19: تنظيم الأسرة | H19: 100
B20: رعاية الأمومة و الطفولة | H20: 50
B21: متابعة الاطفال | H21: 86
B22: IMCI | C22: NA | H22: na
B23: الاسنان | H23: 69
B24: اخرى | H24: 250

Sheet سجل الشكاوى
A1: 📝 سجل الشكاوى
A3: م | B3: تاريخ الشكوي mm/dd/yyyy | C3: نوع الشكوي | D3: ملخص الشكوي | E3: الحل | F3: تاريخ الحل mm/dd/yyyy | G3: التغذية الراجعة | H3: تاريخ التغذية الراجعة mm/dd/yyyy | I3: حل فوري | J3: حل خلال 72 ساعة | K3: زمن الحل(يوم) | L3: الشهر | M3: شهر الحل | N3: شهر التغذية | O3: تصنيفات الشكاوي | P3: تغذية راجعة | Q3: الحل
A4: 1 | B4: 46176 | C4: توافر الأدوية | D4: عدم توافر دواء كذا بالصيدلية لاكثر من شهر | E4: =IF(data_entry[[#This Row],[تاريخ الشكوي mm/dd/yyyy]]="","",IF(data_entry[[#This Row],[تاريخ الحل mm/dd/yyyy]]="","جاري الحل","تم الحل")) -> تم الحل | F4: 46177 | G4: تم التغذية الراجعة | I4: =IF(K4="","",IF(K4=0,"نعم","لا")) -> لا | J4: =IF(data_entry[[#This Row],[زمن الحل(يوم)]]="", "", IF(data_entry[[#This Row],[زمن الحل(يوم)]]<=3, IF(data_entry[[#This Row],[زمن الحل(يوم)]]>0, "نعم", "لا"), "لا")) -> نعم | K4: =IF(OR(data_entry[[#This Row],[تاريخ الشكوي mm/dd/yyyy]]="",data_entry[[#This Row],[تاريخ الحل mm/dd/yyyy]]=""),"",data_entry[[#This Row],[تاريخ الحل mm/dd/yyyy]]-data_entry[[#This Row],[تاريخ الشكوي mm/dd/yyyy]]) -> 1 | L4: =IF(data_entry[[#This Row],[تاريخ الشكوي mm/dd/yyyy]]="","",TEXT(data_entry[[#This Row],[تاريخ الشكوي mm/dd/yyyy]],"mmm-yyyy")) -> Jun-2026 | M4: =IF(data_entry[[#This Row],[تاريخ الحل mm/dd/yyyy]]="","",TEXT(data_entry[[#This Row],[تاريخ الحل mm/dd/yyyy]],"mmm-yyyy")) -> Jun-2026 | N4: =IF(data_entry[[#This Row],[تاريخ التغذية الراجعة mm/dd/yyyy]]="","",TEXT(data_entry[[#This Row],[تاريخ التغذية الراجعة mm/dd/yyyy]],"mmm-yy")) | O4: الاغذية والمطبخ | P4: تم التغذية الراجعة | Q4: تم الحل | R4: 0
A5: 2 | B5: 46178 | C5: وقت الانتظار | D5: طول وقت صرف العلاج | E5: =IF(data_entry[[#This Row],[تاريخ الشكوي mm/dd/yyyy]]="","",IF(data_entry[[#This Row],[تاريخ الحل mm/dd/yyyy]]="","جاري الحل","تم الحل")) -> تم الحل | F5: 46182 | I5: =IF(K5="","",IF(K5=0,"نعم","لا")) -> لا | J5: =IF(data_entry[[#This Row],[زمن الحل(يوم)]]="", "", IF(data_entry[[#This Row],[زمن الحل(يوم)]]<=3, IF(data_entry[[#This Row],[زمن الحل(يوم)]]>0, "نعم", "لا"), "لا")) -> لا | K5: =IF(OR(data_entry[[#This Row],[تاريخ الشكوي mm/dd/yyyy]]="",data_entry[[#This Row],[تاريخ الحل mm/dd/yyyy]]=""),"",data_entry[[#This Row],[تاريخ الحل mm/dd/yyyy]]-data_entry[[#This Row],[تاريخ الشكوي mm/dd/yyyy]]) -> 4 | L5: =IF(data_entry[[#This Row],[تاريخ الشكوي mm/dd/yyyy]]="","",TEXT(data_entry[[#This Row],[تاريخ الشكوي mm/dd/yyyy]],"mmm-yyyy")) -> Jun-2026 | M5: =IF(data_entry[[#This Row],[تاريخ الحل mm/dd/yyyy]]="","",TEXT(data_entry[[#This Row],[تاريخ الحل mm/dd/yyyy]],"mmm-yyyy")) -> Jun-2026 | N5: =IF(data_entry[[#This Row],[تاريخ التغذية الراجعة mm/dd/yyyy]]="","",TEXT(data_entry[[#This Row],[تاريخ التغذية الراجعة mm/dd/yyyy]],"mmm-yy")) | O5: إدارية | P5: لم يتم التغذية الراجعة | Q5: جاري الحل | R5: 1
A6: 3 | B6: 46206 | C6: معاملة الفريق الطبي | D6: معاملة طبيب الاسنان بالعيادة | E6: =IF(data_entry[[#This Row],[تاريخ الشكوي mm/dd/yyyy]]="","",IF(data_entry[[#This Row],[تاريخ الحل mm/dd/yyyy]]="","جاري الحل","تم الحل")) -> تم الحل | F6: 46235 | G6: تم التغذية الراجعة | H6: 46215 | I6: =IF(K6="","",IF(K6=0,"نعم","لا")) -> لا | J6: =IF(data_entry[[#This Row],[زمن الحل(يوم)]]="", "", IF(data_entry[[#This Row],[زمن الحل(يوم)]]<=3, IF(data_entry[[#This Row],[زمن الحل(يوم)]]>0, "نعم", "لا"), "لا")) -> لا | K6: =IF(OR(data_entry[[#This Row],[تاريخ الشكوي mm/dd/yyyy]]="",data_entry[[#This Row],[تاريخ الحل mm/dd/yyyy]]=""),"",data_entry[[#This Row],[تاريخ الحل mm/dd/yyyy]]-data_entry[[#This Row],[تاريخ الشكوي mm/dd/yyyy]]) -> 29 | L6: =IF(data_entry[[#This Row],[تاريخ الشكوي mm/dd/yyyy]]="","",TEXT(data_entry[[#This Row],[تاريخ الشكوي mm/dd/yyyy]],"mmm-yyyy")) -> Jul-2026 | M6: =IF(data_entry[[#This Row],[تاريخ الحل mm/dd/yyyy]]="","",TEXT(data_entry[[#This Row],[تاريخ الحل mm/dd/yyyy]],"mmm-yyyy")) -> Aug-2026 | N6: =IF(data_entry[[#This Row],[تاريخ التغذية الراجعة mm/dd/yyyy]]="","",TEXT(data_entry[[#This Row],[تاريخ التغذية الراجعة mm/dd/yyyy]],"mmm-yy")) -> Jul-26 | O6: إجراءات الدخول | P6: NA
A7: 4 | E7: =IF(data_entry[[#This Row],[تاريخ الشكوي mm/dd/yyyy]]="","",IF(data_entry[[#This Row],[تاريخ الحل mm/dd/yyyy]]="","جاري الحل","تم الحل")) | I7: =IF(K7="","",IF(K7=0,"نعم","لا")) | J7: =IF(data_entry[[#This Row],[زمن الحل(يوم)]]="", "", IF(data_entry[[#This Row],[زمن الحل(يوم)]]<=3, IF(data_entry[[#This Row],[زمن الحل(يوم)]]>0, "نعم", "لا"), "لا")) | K7: =IF(OR(data_entry[[#This Row],[تاريخ الشكوي mm/dd/yyyy]]="",data_entry[[#This Row],[تاريخ الحل mm/dd/yyyy]]=""),"",data_entry[[#This Row],[تاريخ الحل mm/dd/yyyy]]-data_entry[[#This Row],[تاريخ الشكوي mm/dd/yyyy]]) | L7: =IF(data_entry[[#This Row],[تاريخ الشكوي mm/dd/yyyy]]="","",TEXT(data_entry[[#This Row],[تاريخ الشكوي mm/dd/yyyy]],"mmm-yyyy")) | M7: =IF(data_entry[[#This Row],[تاريخ الحل mm/dd/yyyy]]="","",TEXT(data_entry[[#This Row],[تاريخ الحل mm/dd/yyyy]],"mmm-yyyy")) | N7: =IF(data_entry[[#This Row],[تاريخ التغذية الراجعة mm/dd/yyyy]]="","",TEXT(data_entry[[#This Row],[تاريخ التغذية الراجعة mm/dd/yyyy]],"mmm-yy")) | O7: توافر الأدوية
A8: m | E8: =IF(data_entry[[#This Row],[تاريخ الشكوي mm/dd/yyyy]]="","",IF(data_entry[[#This Row],[تاريخ الحل mm/dd/yyyy]]="","جاري الحل","تم الحل")) | I8: =IF(K8="","",IF(K8=0,"نعم","لا")) | J8: =IF(data_entry[[#This Row],[زمن الحل(يوم)]]="", "", IF(data_entry[[#This Row],[زمن الحل(يوم)]]<=3, IF(data_entry[[#This Row],[زمن الحل(يوم)]]>0, "نعم", "لا"), "لا")) | K8: =IF(OR(data_entry[[#This Row],[تاريخ الشكوي mm/dd/yyyy]]="",data_entry[[#This Row],[تاريخ الحل mm/dd/yyyy]]=""),"",data_entry[[#This Row],[تاريخ الحل mm/dd/yyyy]]-data_entry[[#This Row],[تاريخ الشكوي mm/dd/yyyy]]) | L8: =IF(data_entry[[#This Row],[تاريخ الشكوي mm/dd/yyyy]]="","",TEXT(data_entry[[#This Row],[تاريخ الشكوي mm/dd/yyyy]],"mmm-yyyy")) | M8: =IF(data_entry[[#This Row],[تاريخ الحل mm/dd/yyyy]]="","",TEXT(data_entry[[#This Row],[تاريخ الحل mm/dd/yyyy]],"mmm-yyyy")) | N8: =IF(data_entry[[#This Row],[تاريخ التغذية الراجعة mm/dd/yyyy]]="","",TEXT(data_entry[[#This Row],[تاريخ التغذية الراجعة mm/dd/yyyy]],"mmm-yy")) | O8: معاملة الفريق الطبي
A9: 6 | E9: =IF(data_entry[[#This Row],[تاريخ الشكوي mm/dd/yyyy]]="","",IF(data_entry[[#This Row],[تاريخ الحل mm/dd/yyyy]]="","جاري الحل","تم الحل")) | I9: =IF(K9="","",IF(K9=0,"نعم","لا")) | J9: =IF(data_entry[[#This Row],[زمن الحل(يوم)]]="", "", IF(data_entry[[#This Row],[زمن الحل(يوم)]]<=3, IF(data_entry[[#This Row],[زمن الحل(يوم)]]>0, "نعم", "لا"), "لا")) | K9: =IF(OR(data_entry[[#This Row],[تاريخ الشكوي mm/dd/yyyy]]="",data_entry[[#This Row],[تاريخ الحل mm/dd/yyyy]]=""),"",data_entry[[#This Row],[تاريخ الحل mm/dd/yyyy]]-data_entry[[#This Row],[تاريخ الشكوي mm/dd/yyyy]]) | L9: =IF(data_entry[[#This Row],[تاريخ الشكوي mm/dd/yyyy]]="","",TEXT(data_entry[[#This Row],[تاريخ الشكوي mm/dd/yyyy]],"mmm-yyyy")) | M9: =IF(data_entry[[#This Row],[تاريخ الحل mm/dd/yyyy]]="","",TEXT(data_entry[[#This Row],[تاريخ الحل mm/dd/yyyy]],"mmm-yyyy")) | N9: =IF(data_entry[[#This Row],[تاريخ التغذية الراجعة mm/dd/yyyy]]="","",TEXT(data_entry[[#This Row],[تاريخ التغذية الراجعة mm/dd/yyyy]],"mmm-yy")) | O9: وقت الانتظار
A10: 7 | E10: =IF(data_entry[[#This Row],[تاريخ الشكوي mm/dd/yyyy]]="","",IF(data_entry[[#This Row],[تاريخ الحل mm/dd/yyyy]]="","جاري الحل","تم الحل")) | I10: =IF(K10="","",IF(K10=0,"نعم","لا")) | J10: =IF(data_entry[[#This Row],[زمن الحل(يوم)]]="", "", IF(data_entry[[#This Row],[زمن الحل(يوم)]]<=3, IF(data_entry[[#This Row],[زمن الحل(يوم)]]>0, "نعم", "لا"), "لا")) | K10: =IF(OR(data_entry[[#This Row],[تاريخ الشكوي mm/dd/yyyy]]="",data_entry[[#This Row],[تاريخ الحل mm/dd/yyyy]]=""),"",data_entry[[#This Row],[تاريخ الحل mm/dd/yyyy]]-data_entry[[#This Row],[تاريخ الشكوي mm/dd/yyyy]]) | L10: =IF(data_entry[[#This Row],[تاريخ الشكوي mm/dd/yyyy]]="","",TEXT(data_entry[[#This Row],[تاريخ الشكوي mm/dd/yyyy]],"mmm-yyyy")) | M10: =IF(data_entry[[#This Row],[تاريخ الحل mm/dd/yyyy]]="","",TEXT(data_entry[[#This Row],[تاريخ الحل mm/dd/yyyy]],"mmm-yyyy")) | N10: =IF(data_entry[[#This Row],[تاريخ التغذية الراجعة mm/dd/yyyy]]="","",TEXT(data_entry[[#This Row],[تاريخ التغذية الراجعة mm/dd/yyyy]],"mmm-yy")) | O10: اسعار الخدمات
A11: 9 | E11: =IF(data_entry[[#This Row],[تاريخ الشكوي mm/dd/yyyy]]="","",IF(data_entry[[#This Row],[تاريخ الحل mm/dd/yyyy]]="","جاري الحل","تم الحل")) | I11: =IF(K11="","",IF(K11=0,"نعم","لا")) | J11: =IF(data_entry[[#This Row],[زمن الحل(يوم)]]="", "", IF(data_entry[[#This Row],[زمن الحل(يوم)]]<=3, IF(data_entry[[#This Row],[زمن الحل(يوم)]]>0, "نعم", "لا"), "لا")) | K11: =IF(OR(data_entry[[#This Row],[تاريخ الشكوي mm/dd/yyyy]]="",data_entry[[#This Row],[تاريخ الحل mm/dd/yyyy]]=""),"",data_entry[[#This Row],[تاريخ الحل mm/dd/yyyy]]-data_entry[[#This Row],[تاريخ الشكوي mm/dd/yyyy]]) | L11: =IF(data_entry[[#This Row],[تاريخ الشكوي mm/dd/yyyy]]="","",TEXT(data_entry[[#This Row],[تاريخ الشكوي mm/dd/yyyy]],"mmm-yyyy")) | M11: =IF(data_entry[[#This Row],[تاريخ الحل mm/dd/yyyy]]="","",TEXT(data_entry[[#This Row],[تاريخ الحل mm/dd/yyyy]],"mmm-yyyy")) | N11: =IF(data_entry[[#This Row],[تاريخ التغذية الراجعة mm/dd/yyyy]]="","",TEXT(data_entry[[#This Row],[تاريخ التغذية الراجعة mm/dd/yyyy]],"mmm-yy")) | O11: حقوق المرضى
A12: 10 | E12: =IF(data_entry[[#This Row],[تاريخ الشكوي mm/dd/yyyy]]="","",IF(data_entry[[#This Row],[تاريخ الحل mm/dd/yyyy]]="","جاري الحل","تم الحل")) | I12: =IF(K12="","",IF(K12=0,"نعم","لا")) | J12: =IF(data_entry[[#This Row],[زمن الحل(يوم)]]="", "", IF(data_entry[[#This Row],[زمن الحل(يوم)]]<=3, IF(data_entry[[#This Row],[زمن الحل(يوم)]]>0, "نعم", "لا"), "لا")) | K12: =IF(OR(data_entry[[#This Row],[تاريخ الشكوي mm/dd/yyyy]]="",data_entry[[#This Row],[تاريخ الحل mm/dd/yyyy]]=""),"",data_entry[[#This Row],[تاريخ الحل mm/dd/yyyy]]-data_entry[[#This Row],[تاريخ الشكوي mm/dd/yyyy]]) | L12: =IF(data_entry[[#This Row],[تاريخ الشكوي mm/dd/yyyy]]="","",TEXT(data_entry[[#This Row],[تاريخ الشكوي mm/dd/yyyy]],"mmm-yyyy")) | M12: =IF(data_entry[[#This Row],[تاريخ الحل mm/dd/yyyy]]="","",TEXT(data_entry[[#This Row],[تاريخ الحل mm/dd/yyyy]],"mmm-yyyy")) | N12: =IF(data_entry[[#This Row],[تاريخ التغذية الراجعة mm/dd/yyyy]]="","",TEXT(data_entry[[#This Row],[تاريخ التغذية الراجعة mm/dd/yyyy]],"mmm-yy")) | O12: الأمن والنظافة
A13: 11 | E13: =IF(data_entry[[#This Row],[تاريخ الشكوي mm/dd/yyyy]]="","",IF(data_entry[[#This Row],[تاريخ الحل mm/dd/yyyy]]="","جاري الحل","تم الحل")) | I13: =IF(K13="","",IF(K13=0,"نعم","لا")) | J13: =IF(data_entry[[#This Row],[زمن الحل(يوم)]]="", "", IF(data_entry[[#This Row],[زمن الحل(يوم)]]<=3, IF(data_entry[[#This Row],[زمن الحل(يوم)]]>0, "نعم", "لا"), "لا")) | K13: =IF(OR(data_entry[[#This Row],[تاريخ الشكوي mm/dd/yyyy]]="",data_entry[[#This Row],[تاريخ الحل mm/dd/yyyy]]=""),"",data_entry[[#This Row],[تاريخ الحل mm/dd/yyyy]]-data_entry[[#This Row],[تاريخ الشكوي mm/dd/yyyy]]) | L13: =IF(data_entry[[#This Row],[تاريخ الشكوي mm/dd/yyyy]]="","",TEXT(data_entry[[#This Row],[تاريخ الشكوي mm/dd/yyyy]],"mmm-yyyy")) | M13: =IF(data_entry[[#This Row],[تاريخ الحل mm/dd/yyyy]]="","",TEXT(data_entry[[#This Row],[تاريخ الحل mm/dd/yyyy]],"mmm-yyyy")) | N13: =IF(data_entry[[#This Row],[تاريخ التغذية الراجعة mm/dd/yyyy]]="","",TEXT(data_entry[[#This Row],[تاريخ التغذية الراجعة mm/dd/yyyy]],"mmm-yy")) | O13: التحويل والاحالة
A14: 12 | E14: =IF(data_entry[[#This Row],[تاريخ الشكوي mm/dd/yyyy]]="","",IF(data_entry[[#This Row],[تاريخ الحل mm/dd/yyyy]]="","جاري الحل","تم الحل")) | I14: =IF(K14="","",IF(K14=0,"نعم","لا")) | J14: =IF(data_entry[[#This Row],[زمن الحل(يوم)]]="", "", IF(data_entry[[#This Row],[زمن الحل(يوم)]]<=3, IF(data_entry[[#This Row],[زمن الحل(يوم)]]>0, "نعم", "لا"), "لا")) | K14: =IF(OR(data_entry[[#This Row],[تاريخ الشكوي mm/dd/yyyy]]="",data_entry[[#This Row],[تاريخ الحل mm/dd/yyyy]]=""),"",data_entry[[#This Row],[تاريخ الحل mm/dd/yyyy]]-data_entry[[#This Row],[تاريخ الشكوي mm/dd/yyyy]]) | L14: =IF(data_entry[[#This Row],[تاريخ الشكوي mm/dd/yyyy]]="","",TEXT(data_entry[[#This Row],[تاريخ الشكوي mm/dd/yyyy]],"mmm-yyyy")) | M14: =IF(data_entry[[#This Row],[تاريخ الحل mm/dd/yyyy]]="","",TEXT(data_entry[[#This Row],[تاريخ الحل mm/dd/yyyy]],"mmm-yyyy")) | N14: =IF(data_entry[[#This Row],[تاريخ التغذية الراجعة mm/dd/yyyy]]="","",TEXT(data_entry[[#This Row],[تاريخ التغذية الراجعة mm/dd/yyyy]],"mmm-yy")) | O14: الفحوصات الطبية(اشعة/ معمل)
A15: 13 | E15: =IF(data_entry[[#This Row],[تاريخ الشكوي mm/dd/yyyy]]="","",IF(data_entry[[#This Row],[تاريخ الحل mm/dd/yyyy]]="","جاري الحل","تم الحل")) | I15: =IF(K15="","",IF(K15=0,"نعم","لا")) | J15: =IF(data_entry[[#This Row],[زمن الحل(يوم)]]="", "", IF(data_entry[[#This Row],[زمن الحل(يوم)]]<=3, IF(data_entry[[#This Row],[زمن الحل(يوم)]]>0, "نعم", "لا"), "لا")) | K15: =IF(OR(data_entry[[#This Row],[تاريخ الشكوي mm/dd/yyyy]]="",data_entry[[#This Row],[تاريخ الحل mm/dd/yyyy]]=""),"",data_entry[[#This Row],[تاريخ الحل mm/dd/yyyy]]-data_entry[[#This Row],[تاريخ الشكوي mm/dd/yyyy]]) | L15: =IF(data_entry[[#This Row],[تاريخ الشكوي mm/dd/yyyy]]="","",TEXT(data_entry[[#This Row],[تاريخ الشكوي mm/dd/yyyy]],"mmm-yyyy")) | M15: =IF(data_entry[[#This Row],[تاريخ الحل mm/dd/yyyy]]="","",TEXT(data_entry[[#This Row],[تاريخ الحل mm/dd/yyyy]],"mmm-yyyy")) | N15: =IF(data_entry[[#This Row],[تاريخ التغذية الراجعة mm/dd/yyyy]]="","",TEXT(data_entry[[#This Row],[تاريخ التغذية الراجعة mm/dd/yyyy]],"mmm-yy")) | O15: عدم توافر الخدمة
A16: 14 | E16: =IF(data_entry[[#This Row],[تاريخ الشكوي mm/dd/yyyy]]="","",IF(data_entry[[#This Row],[تاريخ الحل mm/dd/yyyy]]="","جاري الحل","تم الحل")) | I16: =IF(K16="","",IF(K16=0,"نعم","لا")) | J16: =IF(data_entry[[#This Row],[زمن الحل(يوم)]]="", "", IF(data_entry[[#This Row],[زمن الحل(يوم)]]<=3, IF(data_entry[[#This Row],[زمن الحل(يوم)]]>0, "نعم", "لا"), "لا")) | K16: =IF(OR(data_entry[[#This Row],[تاريخ الشكوي mm/dd/yyyy]]="",data_entry[[#This Row],[تاريخ الحل mm/dd/yyyy]]=""),"",data_entry[[#This Row],[تاريخ الحل mm/dd/yyyy]]-data_entry[[#This Row],[تاريخ الشكوي mm/dd/yyyy]]) | L16: =IF(data_entry[[#This Row],[تاريخ الشكوي mm/dd/yyyy]]="","",TEXT(data_entry[[#This Row],[تاريخ الشكوي mm/dd/yyyy]],"mmm-yyyy")) | M16: =IF(data_entry[[#This Row],[تاريخ الحل mm/dd/yyyy]]="","",TEXT(data_entry[[#This Row],[تاريخ الحل mm/dd/yyyy]],"mmm-yyyy")) | N16: =IF(data_entry[[#This Row],[تاريخ التغذية الراجعة mm/dd/yyyy]]="","",TEXT(data_entry[[#This Row],[تاريخ التغذية الراجعة mm/dd/yyyy]],"mmm-yy")) | O16: الاعطال و الصيانة
A17: 15 | E17: =IF(data_entry[[#This Row],[تاريخ الشكوي mm/dd/yyyy]]="","",IF(data_entry[[#This Row],[تاريخ الحل mm/dd/yyyy]]="","جاري الحل","تم الحل")) | I17: =IF(K17="","",IF(K17=0,"نعم","لا")) | J17: =IF(data_entry[[#This Row],[زمن الحل(يوم)]]="", "", IF(data_entry[[#This Row],[زمن الحل(يوم)]]<=3, IF(data_entry[[#This Row],[زمن الحل(يوم)]]>0, "نعم", "لا"), "لا")) | K17: =IF(OR(data_entry[[#This Row],[تاريخ الشكوي mm/dd/yyyy]]="",data_entry[[#This Row],[تاريخ الحل mm/dd/yyyy]]=""),"",data_entry[[#This Row],[تاريخ الحل mm/dd/yyyy]]-data_entry[[#This Row],[تاريخ الشكوي mm/dd/yyyy]]) | L17: =IF(data_entry[[#This Row],[تاريخ الشكوي mm/dd/yyyy]]="","",TEXT(data_entry[[#This Row],[تاريخ الشكوي mm/dd/yyyy]],"mmm-yyyy")) | M17: =IF(data_entry[[#This Row],[تاريخ الحل mm/dd/yyyy]]="","",TEXT(data_entry[[#This Row],[تاريخ الحل mm/dd/yyyy]],"mmm-yyyy")) | N17: =IF(data_entry[[#This Row],[تاريخ التغذية الراجعة mm/dd/yyyy]]="","",TEXT(data_entry[[#This Row],[تاريخ التغذية الراجعة mm/dd/yyyy]],"mmm-yy")) | O17: أخرى
A18: 16 | E18: =IF(data_entry[[#This Row],[تاريخ الشكوي mm/dd/yyyy]]="","",IF(data_entry[[#This Row],[تاريخ الحل mm/dd/yyyy]]="","جاري الحل","تم الحل")) | I18: =IF(K18="","",IF(K18=0,"نعم","لا")) | J18: =IF(data_entry[[#This Row],[زمن الحل(يوم)]]="", "", IF(data_entry[[#This Row],[زمن الحل(يوم)]]<=3, IF(data_entry[[#This Row],[زمن الحل(يوم)]]>0, "نعم", "لا"), "لا")) | K18: =IF(OR(data_entry[[#This Row],[تاريخ الشكوي mm/dd/yyyy]]="",data_entry[[#This Row],[تاريخ الحل mm/dd/yyyy]]=""),"",data_entry[[#This Row],[تاريخ الحل mm/dd/yyyy]]-data_entry[[#This Row],[تاريخ الشكوي mm/dd/yyyy]]) | L18: =IF(data_entry[[#This Row],[تاريخ الشكوي mm/dd/yyyy]]="","",TEXT(data_entry[[#This Row],[تاريخ الشكوي mm/dd/yyyy]],"mmm-yyyy")) | M18: =IF(data_entry[[#This Row],[تاريخ الحل mm/dd/yyyy]]="","",TEXT(data_entry[[#This Row],[تاريخ الحل mm/dd/yyyy]],"mmm-yyyy")) | N18: =IF(data_entry[[#This Row],[تاريخ التغذية الراجعة mm/dd/yyyy]]="","",TEXT(data_entry[[#This Row],[تاريخ التغذية الراجعة mm/dd/yyyy]],"mmm-yy"))
A19: 17 | E19: =IF(data_entry[[#This Row],[تاريخ الشكوي mm/dd/yyyy]]="","",IF(data_entry[[#This Row],[تاريخ الحل mm/dd/yyyy]]="","جاري الحل","تم الحل")) | I19: =IF(K19="","",IF(K19=0,"نعم","لا")) | J19: =IF(data_entry[[#This Row],[زمن الحل(يوم)]]="", "", IF(data_entry[[#This Row],[زمن الحل(يوم)]]<=3, IF(data_entry[[#This Row],[زمن الحل(يوم)]]>0, "نعم", "لا"), "لا")) | K19: =IF(OR(data_entry[[#This Row],[تاريخ الشكوي mm/dd/yyyy]]="",data_entry[[#This Row],[تاريخ الحل mm/dd/yyyy]]=""),"",data_entry[[#This Row],[تاريخ الحل mm/dd/yyyy]]-data_entry[[#This Row],[تاريخ الشكوي mm/dd/yyyy]]) | L19: =IF(data_entry[[#This Row],[تاريخ الشكوي mm/dd/yyyy]]="","",TEXT(data_entry[[#This Row],[تاريخ الشكوي mm/dd/yyyy]],"mmm-yyyy")) | M19: =IF(data_entry[[#This Row],[تاريخ الحل mm/dd/yyyy]]="","",TEXT(data_entry[[#This Row],[تاريخ الحل mm/dd/yyyy]],"mmm-yyyy")) | N19: =IF(data_entry[[#This Row],[تاريخ التغذية الراجعة mm/dd/yyyy]]="","",TEXT(data_entry[[#This Row],[تاريخ التغذية الراجعة mm/dd/yyyy]],"mmm-yy"))
A20: 18 | E20: =IF(data_entry[[#This Row],[تاريخ الشكوي mm/dd/yyyy]]="","",IF(data_entry[[#This Row],[تاريخ الحل mm/dd/yyyy]]="","جاري الحل","تم الحل")) | I20: =IF(K20="","",IF(K20=0,"نعم","لا")) | J20: =IF(data_entry[[#This Row],[زمن الحل(يوم)]]="", "", IF(data_entry[[#This Row],[زمن الحل(يوم)]]<=3, IF(data_entry[[#This Row],[زمن الحل(يوم)]]>0, "نعم", "لا"), "لا")) | K20: =IF(OR(data_entry[[#This Row],[تاريخ الشكوي mm/dd/yyyy]]="",data_entry[[#This Row],[تاريخ الحل mm/dd/yyyy]]=""),"",data_entry[[#This Row],[تاريخ الحل mm/dd/yyyy]]-data_entry[[#This Row],[تاريخ الشكوي mm/dd/yyyy]]) | L20: =IF(data_entry[[#This Row],[تاريخ الشكوي mm/dd/yyyy]]="","",TEXT(data_entry[[#This Row],[تاريخ الشكوي mm/dd/yyyy]],"mmm-yyyy")) | M20: =IF(data_entry[[#This Row],[تاريخ الحل mm/dd/yyyy]]="","",TEXT(data_entry[[#This Row],[تاريخ الحل mm/dd/yyyy]],"mmm-yyyy")) | N20: =IF(data_entry[[#This Row],[تاريخ التغذية الراجعة mm/dd/yyyy]]="","",TEXT(data_entry[[#This Row],[تاريخ التغذية الراجعة mm/dd/yyyy]],"mmm-yy"))
A21: 19 | E21: =IF(data_entry[[#This Row],[تاريخ الشكوي mm/dd/yyyy]]="","",IF(data_entry[[#This Row],[تاريخ الحل mm/dd/yyyy]]="","جاري الحل","تم الحل")) | I21: =IF(K21="","",IF(K21=0,"نعم","لا")) | J21: =IF(data_entry[[#This Row],[زمن الحل(يوم)]]="", "", IF(data_entry[[#This Row],[زمن الحل(يوم)]]<=3, IF(data_entry[[#This Row],[زمن الحل(يوم)]]>0, "نعم", "لا"), "لا")) | K21: =IF(OR(data_entry[[#This Row],[تاريخ الشكوي mm/dd/yyyy]]="",data_entry[[#This Row],[تاريخ الحل mm/dd/yyyy]]=""),"",data_entry[[#This Row],[تاريخ الحل mm/dd/yyyy]]-data_entry[[#This Row],[تاريخ الشكوي mm/dd/yyyy]]) | L21: =IF(data_entry[[#This Row],[تاريخ الشكوي mm/dd/yyyy]]="","",TEXT(data_entry[[#This Row],[تاريخ الشكوي mm/dd/yyyy]],"mmm-yyyy")) | M21: =IF(data_entry[[#This Row],[تاريخ الحل mm/dd/yyyy]]="","",TEXT(data_entry[[#This Row],[تاريخ الحل mm/dd/yyyy]],"mmm-yyyy")) | N21: =IF(data_entry[[#This Row],[تاريخ التغذية الراجعة mm/dd/yyyy]]="","",TEXT(data_entry[[#This Row],[تاريخ التغذية الراجعة mm/dd/yyyy]],"mmm-yy"))
A22: 20 | E22: =IF(data_entry[[#This Row],[تاريخ الشكوي mm/dd/yyyy]]="","",IF(data_entry[[#This Row],[تاريخ الحل mm/dd/yyyy]]="","جاري الحل","تم الحل")) | I22: =IF(K22="","",IF(K22=0,"نعم","لا")) | J22: =IF(data_entry[[#This Row],[زمن الحل(يوم)]]="", "", IF(data_entry[[#This Row],[زمن الحل(يوم)]]<=3, IF(data_entry[[#This Row],[زمن الحل(يوم)]]>0, "نعم", "لا"), "لا")) | K22: =IF(OR(data_entry[[#This Row],[تاريخ الشكوي mm/dd/yyyy]]="",data_entry[[#This Row],[تاريخ الحل mm/dd/yyyy]]=""),"",data_entry[[#This Row],[تاريخ الحل mm/dd/yyyy]]-data_entry[[#This Row],[تاريخ الشكوي mm/dd/yyyy]]) | L22: =IF(data_entry[[#This Row],[تاريخ الشكوي mm/dd/yyyy]]="","",TEXT(data_entry[[#This Row],[تاريخ الشكوي mm/dd/yyyy]],"mmm-yyyy")) | M22: =IF(data_entry[[#This Row],[تاريخ الحل mm/dd/yyyy]]="","",TEXT(data_entry[[#This Row],[تاريخ الحل mm/dd/yyyy]],"mmm-yyyy")) | N22: =IF(data_entry[[#This Row],[تاريخ التغذية الراجعة mm/dd/yyyy]]="","",TEXT(data_entry[[#This Row],[تاريخ التغذية الراجعة mm/dd/yyyy]],"mmm-yy"))
A23: 21 | E23: =IF(data_entry[[#This Row],[تاريخ الشكوي mm/dd/yyyy]]="","",IF(data_entry[[#This Row],[تاريخ الحل mm/dd/yyyy]]="","جاري الحل","تم الحل")) | I23: =IF(K23="","",IF(K23=0,"نعم","لا")) | J23: =IF(data_entry[[#This Row],[زمن الحل(يوم)]]="", "", IF(data_entry[[#This Row],[زمن الحل(يوم)]]<=3, IF(data_entry[[#This Row],[زمن الحل(يوم)]]>0, "نعم", "لا"), "لا")) | K23: =IF(OR(data_entry[[#This Row],[تاريخ الشكوي mm/dd/yyyy]]="",data_entry[[#This Row],[تاريخ الحل mm/dd/yyyy]]=""),"",data_entry[[#This Row],[تاريخ الحل mm/dd/yyyy]]-data_entry[[#This Row],[تاريخ الشكوي mm/dd/yyyy]]) | L23: =IF(data_entry[[#This Row],[تاريخ الشكوي mm/dd/yyyy]]="","",TEXT(data_entry[[#This Row],[تاريخ الشكوي mm/dd/yyyy]],"mmm-yyyy")) | M23: =IF(data_entry[[#This Row],[تاريخ الحل mm/dd/yyyy]]="","",TEXT(data_entry[[#This Row],[تاريخ الحل mm/dd/yyyy]],"mmm-yyyy")) | N23: =IF(data_entry[[#This Row],[تاريخ التغذية الراجعة mm/dd/yyyy]]="","",TEXT(data_entry[[#This Row],[تاريخ التغذية الراجعة mm/dd/yyyy]],"mmm-yy"))
A24: 22 | E24: =IF(data_entry[[#This Row],[تاريخ الشكوي mm/dd/yyyy]]="","",IF(data_entry[[#This Row],[تاريخ الحل mm/dd/yyyy]]="","جاري الحل","تم الحل")) | I24: =IF(K24="","",IF(K24=0,"نعم","لا")) | J24: =IF(data_entry[[#This Row],[زمن الحل(يوم)]]="", "", IF(data_entry[[#This Row],[زمن الحل(يوم)]]<=3, IF(data_entry[[#This Row],[زمن الحل(يوم)]]>0, "نعم", "لا"), "لا")) | K24: =IF(OR(data_entry[[#This Row],[تاريخ الشكوي mm/dd/yyyy]]="",data_entry[[#This Row],[تاريخ الحل mm/dd/yyyy]]=""),"",data_entry[[#This Row],[تاريخ الحل mm/dd/yyyy]]-data_entry[[#This Row],[تاريخ الشكوي mm/dd/yyyy]]) | L24: =IF(data_entry[[#This Row],[تاريخ الشكوي mm/dd/yyyy]]="","",TEXT(data_entry[[#This Row],[تاريخ الشكوي mm/dd/yyyy]],"mmm-yyyy")) | M24: =IF(data_entry[[#This Row],[تاريخ الحل mm/dd/yyyy]]="","",TEXT(data_entry[[#This Row],[تاريخ الحل mm/dd/yyyy]],"mmm-yyyy")) | N24: =IF(data_entry[[#This Row],[تاريخ التغذية الراجعة mm/dd/yyyy]]="","",TEXT(data_entry[[#This Row],[تاريخ التغذية الراجعة mm/dd/yyyy]],"mmm-yy"))
A25: 23 | E25: =IF(data_entry[[#This Row],[تاريخ الشكوي mm/dd/yyyy]]="","",IF(data_entry[[#This Row],[تاريخ الحل mm/dd/yyyy]]="","جاري الحل","تم الحل")) | I25: =IF(K25="","",IF(K25=0,"نعم","لا")) | J25: =IF(data_entry[[#This Row],[زمن الحل(يوم)]]="", "", IF(data_entry[[#This Row],[زمن الحل(يوم)]]<=3, IF(data_entry[[#This Row],[زمن الحل(يوم)]]>0, "نعم", "لا"), "لا")) | K25: =IF(OR(data_entry[[#This Row],[تاريخ الشكوي mm/dd/yyyy]]="",data_entry[[#This Row],[تاريخ الحل mm/dd/yyyy]]=""),"",data_entry[[#This Row],[تاريخ الحل mm/dd/yyyy]]-data_entry[[#This Row],[تاريخ الشكوي mm/dd/yyyy]]) | L25: =IF(data_entry[[#This Row],[تاريخ الشكوي mm/dd/yyyy]]="","",TEXT(data_entry[[#This Row],[تاريخ الشكوي mm/dd/yyyy]],"mmm-yyyy")) | M25: =IF(data_entry[[#This Row],[تاريخ الحل mm/dd/yyyy]]="","",TEXT(data_entry[[#This Row],[تاريخ الحل mm/dd/yyyy]],"mmm-yyyy")) | N25: =IF(data_entry[[#This Row],[تاريخ التغذية الراجعة mm/dd/yyyy]]="","",TEXT(data_entry[[#This Row],[تاريخ التغذية الراجعة mm/dd/yyyy]],"mmm-yy"))
A26: 24 | E26: =IF(data_entry[[#This Row],[تاريخ الشكوي mm/dd/yyyy]]="","",IF(data_entry[[#This Row],[تاريخ الحل mm/dd/yyyy]]="","جاري الحل","تم الحل")) | I26: =IF(K26="","",IF(K26=0,"نعم","لا")) | J26: =IF(data_entry[[#This Row],[زمن الحل(يوم)]]="", "", IF(data_entry[[#This Row],[زمن الحل(يوم)]]<=3, IF(data_entry[[#This Row],[زمن الحل(يوم)]]>0, "نعم", "لا"), "لا")) | K26: =IF(OR(data_entry[[#This Row],[تاريخ الشكوي mm/dd/yyyy]]="",data_entry[[#This Row],[تاريخ الحل mm/dd/yyyy]]=""),"",data_entry[[#This Row],[تاريخ الحل mm/dd/yyyy]]-data_entry[[#This Row],[تاريخ الشكوي mm/dd/yyyy]]) | L26: =IF(data_entry[[#This Row],[تاريخ الشكوي mm/dd/yyyy]]="","",TEXT(data_entry[[#This Row],[تاريخ الشكوي mm/dd/yyyy]],"mmm-yyyy")) | M26: =IF(data_entry[[#This Row],[تاريخ الحل mm/dd/yyyy]]="","",TEXT(data_entry[[#This Row],[تاريخ الحل mm/dd/yyyy]],"mmm-yyyy")) | N26: =IF(data_entry[[#This Row],[تاريخ التغذية الراجعة mm/dd/yyyy]]="","",TEXT(data_entry[[#This Row],[تاريخ التغذية الراجعة mm/dd/yyyy]],"mmm-yy"))
A27: 25 | E27: =IF(data_entry[[#This Row],[تاريخ الشكوي mm/dd/yyyy]]="","",IF(data_entry[[#This Row],[تاريخ الحل mm/dd/yyyy]]="","جاري الحل","تم الحل")) | I27: =IF(K27="","",IF(K27=0,"نعم","لا")) | J27: =IF(data_entry[[#This Row],[زمن الحل(يوم)]]="", "", IF(data_entry[[#This Row],[زمن الحل(يوم)]]<=3, IF(data_entry[[#This Row],[زمن الحل(يوم)]]>0, "نعم", "لا"), "لا")) | K27: =IF(OR(data_entry[[#This Row],[تاريخ الشكوي mm/dd/yyyy]]="",data_entry[[#This Row],[تاريخ الحل mm/dd/yyyy]]=""),"",data_entry[[#This Row],[تاريخ الحل mm/dd/yyyy]]-data_entry[[#This Row],[تاريخ الشكوي mm/dd/yyyy]]) | L27: =IF(data_entry[[#This Row],[تاريخ الشكوي mm/dd/yyyy]]="","",TEXT(data_entry[[#This Row],[تاريخ الشكوي mm/dd/yyyy]],"mmm-yyyy")) | M27: =IF(data_entry[[#This Row],[تاريخ الحل mm/dd/yyyy]]="","",TEXT(data_entry[[#This Row],[تاريخ الحل mm/dd/yyyy]],"mmm-yyyy")) | N27: =IF(data_entry[[#This Row],[تاريخ التغذية الراجعة mm/dd/yyyy]]="","",TEXT(data_entry[[#This Row],[تاريخ التغذية الراجعة mm/dd/yyyy]],"mmm-yy"))
A28: 26 | E28: =IF(data_entry[[#This Row],[تاريخ الشكوي mm/dd/yyyy]]="","",IF(data_entry[[#This Row],[تاريخ الحل mm/dd/yyyy]]="","جاري الحل","تم الحل")) | I28: =IF(K28="","",IF(K28=0,"نعم","لا")) | J28: =IF(data_entry[[#This Row],[زمن الحل(يوم)]]="", "", IF(data_entry[[#This Row],[زمن الحل(يوم)]]<=3, IF(data_entry[[#This Row],[زمن الحل(يوم)]]>0, "نعم", "لا"), "لا")) | K28: =IF(OR(data_entry[[#This Row],[تاريخ الشكوي mm/dd/yyyy]]="",data_entry[[#This Row],[تاريخ الحل mm/dd/yyyy]]=""),"",data_entry[[#This Row],[تاريخ الحل mm/dd/yyyy]]-data_entry[[#This Row],[تاريخ الشكوي mm/dd/yyyy]]) | L28: =IF(data_entry[[#This Row],[تاريخ الشكوي mm/dd/yyyy]]="","",TEXT(data_entry[[#This Row],[تاريخ الشكوي mm/dd/yyyy]],"mmm-yyyy")) | M28: =IF(data_entry[[#This Row],[تاريخ الحل mm/dd/yyyy]]="","",TEXT(data_entry[[#This Row],[تاريخ الحل mm/dd/yyyy]],"mmm-yyyy")) | N28: =IF(data_entry[[#This Row],[تاريخ التغذية الراجعة mm/dd/yyyy]]="","",TEXT(data_entry[[#This Row],[تاريخ التغذية الراجعة mm/dd/yyyy]],"mmm-yy"))
A29: 27 | E29: =IF(data_entry[[#This Row],[تاريخ الشكوي mm/dd/yyyy]]="","",IF(data_entry[[#This Row],[تاريخ الحل mm/dd/yyyy]]="","جاري الحل","تم الحل")) | I29: =IF(K29="","",IF(K29=0,"نعم","لا")) | J29: =IF(data_entry[[#This Row],[زمن الحل(يوم)]]="", "", IF(data_entry[[#This Row],[زمن الحل(يوم)]]<=3, IF(data_entry[[#This Row],[زمن الحل(يوم)]]>0, "نعم", "لا"), "لا")) | K29: =IF(OR(data_entry[[#This Row],[تاريخ الشكوي mm/dd/yyyy]]="",data_entry[[#This Row],[تاريخ الحل mm/dd/yyyy]]=""),"",data_entry[[#This Row],[تاريخ الحل mm/dd/yyyy]]-data_entry[[#This Row],[تاريخ الشكوي mm/dd/yyyy]]) | L29: =IF(data_entry[[#This Row],[تاريخ الشكوي mm/dd/yyyy]]="","",TEXT(data_entry[[#This Row],[تاريخ الشكوي mm/dd/yyyy]],"mmm-yyyy")) | M29: =IF(data_entry[[#This Row],[تاريخ الحل mm/dd/yyyy]]="","",TEXT(data_entry[[#This Row],[تاريخ الحل mm/dd/yyyy]],"mmm-yyyy")) | N29: =IF(data_entry[[#This Row],[تاريخ التغذية الراجعة mm/dd/yyyy]]="","",TEXT(data_entry[[#This Row],[تاريخ التغذية الراجعة mm/dd/yyyy]],"mmm-yy"))
... A352: 350 | E352: =IF(data_entry[[#This Row],[تاريخ الشكوي mm/dd/yyyy]]="","",IF(data_entry[[#This Row],[تاريخ الحل mm/dd/yyyy]]="","جاري الحل","تم الحل")) | I352: =IF(K352="","",IF(K352=0,"نعم","لا")) | J352: =IF(data_entry[[#This Row],[زمن الحل(يوم)]]="", "", IF(data_entry[[#This Row],[زمن الحل(يوم)]]<=3, IF(data_entry[[#This Row],[زمن الحل(يوم)]]>0, "نعم", "لا"), "لا")) | K352: =IF(OR(data_entry[[#This Row],[تاريخ الشكوي mm/dd/yyyy]]="",data_entry[[#This Row],[تاريخ الحل mm/dd/yyyy]]=""),"",data_entry[[#This Row],[تاريخ الحل mm/dd/yyyy]]-data_entry[[#This Row],[تاريخ الشكوي mm/dd/yyyy]]) | L352: =IF(data_entry[[#This Row],[تاريخ الشكوي mm/dd/yyyy]]="","",TEXT(data_entry[[#This Row],[تاريخ الشكوي mm/dd/yyyy]],"mmm-yyyy")) | M352: =IF(data_entry[[#This Row],[تاريخ الحل mm/dd/yyyy]]="","",TEXT(data_entry[[#This Row],[تاريخ الحل mm/dd/yyyy]],"mmm-yyyy")) | N352: =IF(data_entry[[#This Row],[تاريخ التغذية الراجعة mm/dd/yyyy]]="","",TEXT(data_entry[[#This Row],[تاريخ التغذية الراجعة mm/dd/yyyy]],"mmm-yy"))

Sheet تدريب
A1: 🎓 سجل التدريب
A3: م | B3: البند | C3: Jan-26 | D3: Feb-26 | E3: Mar-26 | F3: Apr-26 | G3: May-26 | H3: Jun-26 | I3: Jul-26 | J3: Aug-26 | K3: Sep-26 | L3: Oct-26 | M3: Nov-26 | N3: Dec-26
A4: 1 | B4: اجمالي عدد الاطباء بالوحدة | C4: 12 | F4: 12
A5: 2 | B5: اجمالي عدد التمريض بالوحدة | C5: 20 | F5: 25
A6: 3 | B6: اجمالي عدد العاملين بالوحدة | C6: 60 | F6: 65
A7: 4 | B7: عدد الاطباء المدربين على BLS (شهادة معتمدة) | C7: 6 | F7: 6
A8: 5 | B8: عدد اعضاء هيئة التمريض المدربين على BLS(شهادة معتمدة) | C8: 15 | F8: 15
A9: 6 | B9: عدد العاملين المدربين على الدفاع المدني (شهادات معتمدة) | C9: 12 | F9: 12

Sheet الإفاقة القلبية
A1: ❤️ سجل الإفاقة القلبية التنفسية (CPR)
A2: ⚠️ يُستخدم هذا السجل لتوثيق جميع حالات توقف القلب والإنعاش القلبي الرئوي
A4: م | B4: اسم المريض | C4: الرقم الطبي | D4: تاريخ حدوث توقف القلب mm/dd/yyyy | E4: مكان حدوث توقف القلب | F4: وقت اعلان Code Blue | G4: وقت بداية CPR | H4: وقت وصول فريق الCode Blue كاملا | I4: زمن الاستجابة للCode Blue | J4: عدد دورات CPR (2نفس/30 ضغطة) | K4: وقت انتهاء CPR | L4: مدة الانعاش الكلية | M4: نتيجة الانعاش عند الانتهاء (نجاة / وفاة) | N4: نموذج التوثيق كامل البيانات | O4: شهر حدوث الحدث | P4: Column1 | Q4: الرعاية المركزة | R4: نعم | S4: وفاة | T4: نجاة | U4: 10 | V4: 11
A5: 1 | B5: تجربة للافاقة القلبية | C5: 5463 | D5: 46180 | E5: وحدة رعاية أولية | F5: 0.52083333 | G5: 0.52083333 | H5: 0.52361111 | I5: ='الإفاقة القلبية'!$H5-'الإفاقة القلبية'!$F5 -> 0.0027777778 | J5: 35 | K5: 0.53055556 | L5: ='الإفاقة القلبية'!$K5-'الإفاقة القلبية'!$G5 -> 0.0097222222 | M5: وفاة | N5: نعم | O5: =IF(Table6[[#This Row],[تاريخ حدوث توقف القلب mm/dd/yyyy]]="","",TEXT(Table6[[#This Row],[تاريخ حدوث توقف القلب mm/dd/yyyy]],"mmm-yyyy")) -> Jun-2026 | Q5: الحضانات | R5: لا | S5: تحسن | T5: وفاة | U5: 10
A6: 2 | B6: تجربة للافاقة القلبية | D6: 46176 | E6: وحدة رعاية أولية | F6: 0.41666667 | G6: 0.41666667 | H6: 0.42916667 | I6: ='الإفاقة القلبية'!$H6-'الإفاقة القلبية'!$F6 -> 0.0125 | L6: ='الإفاقة القلبية'!$K6-'الإفاقة القلبية'!$G6 -> -0.41666667 | O6: =IF(Table6[[#This Row],[تاريخ حدوث توقف القلب mm/dd/yyyy]]="","",TEXT(Table6[[#This Row],[تاريخ حدوث توقف القلب mm/dd/yyyy]],"mmm-yyyy")) -> Jun-2026 | Q6: الطوارئ والاستقبال | S6: نقل/إحالة | U6: 10
A7: 3 | I7: ='الإفاقة القلبية'!$H7-'الإفاقة القلبية'!$F7 -> 0 | L7: ='الإفاقة القلبية'!$K7-'الإفاقة القلبية'!$G7 -> 0 | O7: =IF(Table6[[#This Row],[تاريخ حدوث توقف القلب mm/dd/yyyy]]="","",TEXT(Table6[[#This Row],[تاريخ حدوث توقف القلب mm/dd/yyyy]],"mmm-yyyy")) | Q7: الغسيل الكلوي | U7: 10
A8: 4 | I8: ='الإفاقة القلبية'!$H8-'الإفاقة القلبية'!$F8 -> 0 | L8: ='الإفاقة القلبية'!$K8-'الإفاقة القلبية'!$G8 -> 0 | O8: =IF(Table6[[#This Row],[تاريخ حدوث توقف القلب mm/dd/yyyy]]="","",TEXT(Table6[[#This Row],[تاريخ حدوث توقف القلب mm/dd/yyyy]],"mmm-yyyy")) | Q8: العمليات | U8: 10
A9: 5 | I9: ='الإفاقة القلبية'!$H9-'الإفاقة القلبية'!$F9 -> 0 | L9: ='الإفاقة القلبية'!$K9-'الإفاقة القلبية'!$G9 -> 0 | O9: =IF(Table6[[#This Row],[تاريخ حدوث توقف القلب mm/dd/yyyy]]="","",TEXT(Table6[[#This Row],[تاريخ حدوث توقف القلب mm/dd/yyyy]],"mmm-yyyy")) | Q9: الأقسام الداخلية | U9: 10
A10: 6 | I10: ='الإفاقة القلبية'!$H10-'الإفاقة القلبية'!$F10 -> 0 | L10: ='الإفاقة القلبية'!$K10-'الإفاقة القلبية'!$G10 -> 0 | O10: =IF(Table6[[#This Row],[تاريخ حدوث توقف القلب mm/dd/yyyy]]="","",TEXT(Table6[[#This Row],[تاريخ حدوث توقف القلب mm/dd/yyyy]],"mmm-yyyy")) | Q10: أخرى | U10: 10
A11: 7 | I11: ='الإفاقة القلبية'!$H11-'الإفاقة القلبية'!$F11 -> 0 | L11: ='الإفاقة القلبية'!$K11-'الإفاقة القلبية'!$G11 -> 0 | O11: =IF(Table6[[#This Row],[تاريخ حدوث توقف القلب mm/dd/yyyy]]="","",TEXT(Table6[[#This Row],[تاريخ حدوث توقف القلب mm/dd/yyyy]],"mmm-yyyy")) | Q11: وحدة رعاية أولية | U11: 10
A12: 8 | I12: ='الإفاقة القلبية'!$H12-'الإفاقة القلبية'!$F12 -> 0 | L12: ='الإفاقة القلبية'!$K12-'الإفاقة القلبية'!$G12 -> 0 | O12: =IF(Table6[[#This Row],[تاريخ حدوث توقف القلب mm/dd/yyyy]]="","",TEXT(Table6[[#This Row],[تاريخ حدوث توقف القلب mm/dd/yyyy]],"mmm-yyyy")) | U12: 10
A13: 9 | I13: ='الإفاقة القلبية'!$H13-'الإفاقة القلبية'!$F13 -> 0 | L13: ='الإفاقة القلبية'!$K13-'الإفاقة القلبية'!$G13 -> 0 | O13: =IF(Table6[[#This Row],[تاريخ حدوث توقف القلب mm/dd/yyyy]]="","",TEXT(Table6[[#This Row],[تاريخ حدوث توقف القلب mm/dd/yyyy]],"mmm-yyyy")) | U13: 10
A14: 10 | I14: ='الإفاقة القلبية'!$H14-'الإفاقة القلبية'!$F14 -> 0 | L14: ='الإفاقة القلبية'!$K14-'الإفاقة القلبية'!$G14 -> 0 | O14: =IF(Table6[[#This Row],[تاريخ حدوث توقف القلب mm/dd/yyyy]]="","",TEXT(Table6[[#This Row],[تاريخ حدوث توقف القلب mm/dd/yyyy]],"mmm-yyyy")) | U14: 10
A15: 11 | I15: ='الإفاقة القلبية'!$H15-'الإفاقة القلبية'!$F15 -> 0 | L15: ='الإفاقة القلبية'!$K15-'الإفاقة القلبية'!$G15 -> 0 | O15: =IF(Table6[[#This Row],[تاريخ حدوث توقف القلب mm/dd/yyyy]]="","",TEXT(Table6[[#This Row],[تاريخ حدوث توقف القلب mm/dd/yyyy]],"mmm-yyyy")) | U15: 10
A16: 12 | I16: ='الإفاقة القلبية'!$H16-'الإفاقة القلبية'!$F16 -> 0 | L16: ='الإفاقة القلبية'!$K16-'الإفاقة القلبية'!$G16 -> 0 | O16: =IF(Table6[[#This Row],[تاريخ حدوث توقف القلب mm/dd/yyyy]]="","",TEXT(Table6[[#This Row],[تاريخ حدوث توقف القلب mm/dd/yyyy]],"mmm-yyyy")) | U16: 10
A17: 13 | I17: ='الإفاقة القلبية'!$H17-'الإفاقة القلبية'!$F17 -> 0 | L17: ='الإفاقة القلبية'!$K17-'الإفاقة القلبية'!$G17 -> 0 | O17: =IF(Table6[[#This Row],[تاريخ حدوث توقف القلب mm/dd/yyyy]]="","",TEXT(Table6[[#This Row],[تاريخ حدوث توقف القلب mm/dd/yyyy]],"mmm-yyyy")) | U17: 10
A18: 14 | I18: ='الإفاقة القلبية'!$H18-'الإفاقة القلبية'!$F18 -> 0 | L18: ='الإفاقة القلبية'!$K18-'الإفاقة القلبية'!$G18 -> 0 | O18: =IF(Table6[[#This Row],[تاريخ حدوث توقف القلب mm/dd/yyyy]]="","",TEXT(Table6[[#This Row],[تاريخ حدوث توقف القلب mm/dd/yyyy]],"mmm-yyyy")) | U18: 10
A19: 15 | I19: ='الإفاقة القلبية'!$H19-'الإفاقة القلبية'!$F19 -> 0 | L19: ='الإفاقة القلبية'!$K19-'الإفاقة القلبية'!$G19 -> 0 | O19: =IF(Table6[[#This Row],[تاريخ حدوث توقف القلب mm/dd/yyyy]]="","",TEXT(Table6[[#This Row],[تاريخ حدوث توقف القلب mm/dd/yyyy]],"mmm-yyyy")) | U19: 10
A20: 16 | I20: ='الإفاقة القلبية'!$H20-'الإفاقة القلبية'!$F20 -> 0 | L20: ='الإفاقة القلبية'!$K20-'الإفاقة القلبية'!$G20 -> 0 | O20: =IF(Table6[[#This Row],[تاريخ حدوث توقف القلب mm/dd/yyyy]]="","",TEXT(Table6[[#This Row],[تاريخ حدوث توقف القلب mm/dd/yyyy]],"mmm-yyyy")) | U20: 10
A21: 17 | I21: ='الإفاقة القلبية'!$H21-'الإفاقة القلبية'!$F21 -> 0 | L21: ='الإفاقة القلبية'!$K21-'الإفاقة القلبية'!$G21 -> 0 | O21: =IF(Table6[[#This Row],[تاريخ حدوث توقف القلب mm/dd/yyyy]]="","",TEXT(Table6[[#This Row],[تاريخ حدوث توقف القلب mm/dd/yyyy]],"mmm-yyyy")) | U21: 10
A22: 18 | I22: ='الإفاقة القلبية'!$H22-'الإفاقة القلبية'!$F22 -> 0 | L22: ='الإفاقة القلبية'!$K22-'الإفاقة القلبية'!$G22 -> 0 | O22: =IF(Table6[[#This Row],[تاريخ حدوث توقف القلب mm/dd/yyyy]]="","",TEXT(Table6[[#This Row],[تاريخ حدوث توقف القلب mm/dd/yyyy]],"mmm-yyyy")) | U22: 10
A23: 19 | I23: ='الإفاقة القلبية'!$H23-'الإفاقة القلبية'!$F23 -> 0 | L23: ='الإفاقة القلبية'!$K23-'الإفاقة القلبية'!$G23 -> 0 | O23: =IF(Table6[[#This Row],[تاريخ حدوث توقف القلب mm/dd/yyyy]]="","",TEXT(Table6[[#This Row],[تاريخ حدوث توقف القلب mm/dd/yyyy]],"mmm-yyyy")) | U23: 10
... A203: 199 | I203: ='الإفاقة القلبية'!$H203-'الإفاقة القلبية'!$F203 -> 0 | L203: ='الإفاقة القلبية'!$K203-'الإفاقة القلبية'!$G203 -> 0 | O203: =IF(Table6[[#This Row],[تاريخ حدوث توقف القلب mm/dd/yyyy]]="","",TEXT(Table6[[#This Row],[تاريخ حدوث توقف القلب mm/dd/yyyy]],"mmm-yyyy")) | U203: 10
A204: 200 | I204: ='الإفاقة القلبية'!$H204-'الإفاقة القلبية'!$F204 -> 0 | L204: ='الإفاقة القلبية'!$K204-'الإفاقة القلبية'!$G204 -> 0 | O204: =IF(Table6[[#This Row],[تاريخ حدوث توقف القلب mm/dd/yyyy]]="","",TEXT(Table6[[#This Row],[تاريخ حدوث توقف القلب mm/dd/yyyy]],"mmm-yyyy"))

Sheet الطوارئ والاستقبال
A1: 🚨 سجل الطوارئ والاستقبال
A3: م | B3: التاريخ | C3: اسم المريض | D3: الرقم الطبي/ رقم السجل | E3: تاريخ الزيارة mm/dd/yyyy | F3: ساعة الدخول | G3: ساعة الخروج | H3: الوقت المستغرق | J3: الشهر | K3: عدد مرضى اعادة الدخول خلال 72 ساعة | L3: اجمالي مرضى الطوارئ | N3: شهر الزيارة
A4: 1 | B4: 46174 | C4: محمود سيد احمد | D4: 12345 | E4: 46174 | F4: 0.52361111 | G4: 0.53194444 | H4: =G4-F4 -> 0.0083333333 | J4: 46023 | N4: =IF(E4="","",TEXT(E4,"mmm-yyyy")) -> Jun-2026 | O4: 10
A5: 2 | B5: 46175 | C5: محمود سيد احمد | D5: 12346 | E5: 46175 | F5: 0.52361111 | G5: 0.53194444 | H5: =G5-F5 -> 0.0083333333 | J5: 46054 | N5: =IF(E5="","",TEXT(E5,"mmm-yyyy")) -> Jun-2026 | O5: 10
A6: 3 | B6: 46176 | C6: محمود سيد احمد | D6: 12347 | E6: 46176 | F6: 0.52361111 | G6: 0.53194444 | H6: =G6-F6 -> 0.0083333333 | J6: 46082 | N6: =IF(E6="","",TEXT(E6,"mmm-yyyy")) -> Jun-2026 | O6: 10
A7: 4 | H7: =G7-F7 -> 0 | J7: 46113 | N7: =IF(E7="","",TEXT(E7,"mmm-yyyy")) | O7: 10
A8: 5 | H8: =G8-F8 -> 0 | J8: 46143 | N8: =IF(E8="","",TEXT(E8,"mmm-yyyy")) | O8: 10
A9: 6 | H9: =G9-F9 -> 0 | J9: 46174 | K9: 5 | L9: 200 | N9: =IF(E9="","",TEXT(E9,"mmm-yyyy")) | O9: 10
A10: 7 | H10: =G10-F10 -> 0 | J10: 46204 | N10: =IF(E10="","",TEXT(E10,"mmm-yyyy")) | O10: 10
A11: 8 | H11: =G11-F11 -> 0 | J11: 46235 | N11: =IF(E11="","",TEXT(E11,"mmm-yyyy")) | O11: 10
A12: 9 | H12: =G12-F12 -> 0 | J12: 46266 | N12: =IF(E12="","",TEXT(E12,"mmm-yyyy")) | O12: 10
A13: 10 | H13: =G13-F13 -> 0 | J13: 46296 | N13: =IF(E13="","",TEXT(E13,"mmm-yyyy")) | O13: 10
A14: 11 | H14: =G14-F14 -> 0 | J14: 46327 | N14: =IF(E14="","",TEXT(E14,"mmm-yyyy")) | O14: 10
A15: 12 | H15: =G15-F15 -> 0 | J15: 46357 | N15: =IF(E15="","",TEXT(E15,"mmm-yyyy")) | O15: 10
A16: 13 | H16: =G16-F16 -> 0 | N16: =IF(E16="","",TEXT(E16,"mmm-yyyy")) | O16: 10
A17: 14 | H17: =G17-F17 -> 0 | N17: =IF(E17="","",TEXT(E17,"mmm-yyyy")) | O17: 10
A18: 15 | H18: =G18-F18 -> 0 | N18: =IF(E18="","",TEXT(E18,"mmm-yyyy")) | O18: 10
A19: 16 | H19: =G19-F19 -> 0 | N19: =IF(E19="","",TEXT(E19,"mmm-yyyy")) | O19: 10
A20: 17 | H20: =G20-F20 -> 0 | N20: =IF(E20="","",TEXT(E20,"mmm-yyyy")) | O20: 10
A21: 18 | H21: =G21-F21 -> 0 | N21: =IF(E21="","",TEXT(E21,"mmm-yyyy")) | O21: 10
A22: 19 | H22: =G22-F22 -> 0 | N22: =IF(E22="","",TEXT(E22,"mmm-yyyy")) | O22: 10
A23: 20 | H23: =G23-F23 -> 0 | N23: =IF(E23="","",TEXT(E23,"mmm-yyyy")) | O23: 10
A24: 21 | H24: =G24-F24 -> 0 | N24: =IF(E24="","",TEXT(E24,"mmm-yyyy")) | O24: 10
A25: 22 | H25: =G25-F25 -> 0 | N25: =IF(E25="","",TEXT(E25,"mmm-yyyy")) | O25: 10
A26: 23 | H26: =G26-F26 -> 0 | N26: =IF(E26="","",TEXT(E26,"mmm-yyyy")) | O26: 10
A27: 24 | H27: =G27-F27 -> 0 | N27: =IF(E27="","",TEXT(E27,"mmm-yyyy")) | O27: 10
... A243: 240 | H243: =G243-F243 -> 0 | N243: =IF(E243="","",TEXT(E243,"mmm-yyyy")) | O243: 10

Sheet الاجمالي الشهري
A1: 📅 الإجمالي الشهري
A3: Column1 | B3: Column2 | C3: Column3 | D3: Column4 | E3: Column5 | F3: Column6 | G3: Column7 | H3: Column8 | I3: Column9 | J3: Column10 | K3: Column11 | L3: Column12 | M3: Column13
A4: البند | B4: 46023 | C4: 46054 | D4: 46082 | E4: 46113 | F4: 46143 | G4: 46174 | H4: 46204 | I4: 46235 | J4: 46266 | K4: 46296 | L4: 46327 | M4: 46357
A5: 📋 الشكاوى
A6: إجمالي عدد الشكاوى | B6: =COUNTIF(data_entry[الشهر],B4) -> 0 | C6: =COUNTIF(data_entry[الشهر],C4) -> 0 | D6: =COUNTIF(data_entry[الشهر],D4) -> 0 | E6: =COUNTIF(data_entry[الشهر],E4) -> 0 | F6: =COUNTIF(data_entry[الشهر],F4) -> 0 | G6: =COUNTIF(data_entry[الشهر],G4) -> 2 | H6: =COUNTIF(data_entry[الشهر],H4) -> 1 | I6: =COUNTIF(data_entry[الشهر],I4) -> 0 | ... M6: =COUNTIF(data_entry[الشهر],M4) -> 0
A7: إجمالي عدد الشكاوى التي تم حلها | B7: =COUNTIFS(data_entry[الشهر],B$4,data_entry[شهر الحل],B$4,data_entry[الحل],"تم الحل") -> 0 | C7: =COUNTIFS(data_entry[الشهر],C$4,data_entry[شهر الحل],C$4,data_entry[الحل],"تم الحل") -> 0 | D7: =COUNTIFS(data_entry[الشهر],D$4,data_entry[شهر الحل],D$4,data_entry[الحل],"تم الحل") -> 0 | E7: =COUNTIFS(data_entry[الشهر],E$4,data_entry[شهر الحل],E$4,data_entry[الحل],"تم الحل") -> 0 | F7: =COUNTIFS(data_entry[الشهر],F$4,data_entry[شهر الحل],F$4,data_entry[الحل],"تم الحل") -> 0 | G7: =COUNTIFS(data_entry[الشهر],G$4,data_entry[شهر الحل],G$4,data_entry[الحل],"تم الحل") -> 2 | H7: =COUNTIFS(data_entry[الشهر],H$4,data_entry[شهر الحل],H$4,data_entry[الحل],"تم الحل") -> 0 | I7: =COUNTIFS(data_entry[الشهر],I$4,data_entry[شهر الحل],I$4,data_entry[الحل],"تم الحل") -> 0 | ... M7: =COUNTIFS(data_entry[الشهر],M$4,data_entry[شهر الحل],M$4,data_entry[الحل],"تم الحل") -> 0
A8: إجمالي عدد الشكاوى التي تم حلها فوريا | B8: =COUNTIFS(data_entry[الشهر],B$4,data_entry[حل فوري],"نعم") -> 0 | C8: =COUNTIFS(data_entry[الشهر],C$4,data_entry[حل فوري],"نعم") -> 0 | D8: =COUNTIFS(data_entry[الشهر],D$4,data_entry[حل فوري],"نعم") -> 0 | E8: =COUNTIFS(data_entry[الشهر],E$4,data_entry[حل فوري],"نعم") -> 0 | F8: =COUNTIFS(data_entry[الشهر],F$4,data_entry[حل فوري],"نعم") -> 0 | G8: =COUNTIFS(data_entry[الشهر],G$4,data_entry[حل فوري],"نعم") -> 0 | H8: =COUNTIFS(data_entry[الشهر],H$4,data_entry[حل فوري],"نعم") -> 0 | I8: =COUNTIFS(data_entry[الشهر],I$4,data_entry[حل فوري],"نعم") -> 0 | ... M8: =COUNTIFS(data_entry[الشهر],M$4,data_entry[حل فوري],"نعم") -> 0
A9: إجمالي عدد الشكاوى التي تم حلها خلال 72 ساعة | B9: =COUNTIFS(data_entry[الشهر],B$4,data_entry[شهر الحل],B$4,data_entry[حل خلال 72 ساعة],"نعم") -> 0 | C9: =COUNTIFS(data_entry[الشهر],C$4,data_entry[شهر الحل],C$4,data_entry[حل خلال 72 ساعة],"نعم") -> 0 | D9: =COUNTIFS(data_entry[الشهر],D$4,data_entry[شهر الحل],D$4,data_entry[حل خلال 72 ساعة],"نعم") -> 0 | E9: =COUNTIFS(data_entry[الشهر],E$4,data_entry[شهر الحل],E$4,data_entry[حل خلال 72 ساعة],"نعم") -> 0 | F9: =COUNTIFS(data_entry[الشهر],F$4,data_entry[شهر الحل],F$4,data_entry[حل خلال 72 ساعة],"نعم") -> 0 | G9: =COUNTIFS(data_entry[الشهر],G$4,data_entry[شهر الحل],G$4,data_entry[حل خلال 72 ساعة],"نعم") -> 1 | H9: =COUNTIFS(data_entry[الشهر],H$4,data_entry[شهر الحل],H$4,data_entry[حل خلال 72 ساعة],"نعم") -> 0 | I9: =COUNTIFS(data_entry[الشهر],I$4,data_entry[شهر الحل],I$4,data_entry[حل خلال 72 ساعة],"نعم") -> 0 | ... M9: =COUNTIFS(data_entry[الشهر],M$4,data_entry[شهر الحل],M$4,data_entry[حل خلال 72 ساعة],"نعم") -> 0
A10: عدد الشكاوى التي تم عمل تغذية راجعة لمقدم الشكوى | B10: =COUNTIFS(data_entry[الشهر],B4,data_entry[التغذية الراجعة],"تم التغذية الراجعة") -> 0 | C10: =COUNTIFS(data_entry[الشهر],C4,data_entry[التغذية الراجعة],"تم التغذية الراجعة") -> 0 | D10: =COUNTIFS(data_entry[الشهر],D4,data_entry[التغذية الراجعة],"تم التغذية الراجعة") -> 0 | E10: =COUNTIFS(data_entry[الشهر],E4,data_entry[التغذية الراجعة],"تم التغذية الراجعة") -> 0 | F10: =COUNTIFS(data_entry[الشهر],F4,data_entry[التغذية الراجعة],"تم التغذية الراجعة") -> 0 | G10: =COUNTIFS(data_entry[الشهر],G4,data_entry[التغذية الراجعة],"تم التغذية الراجعة") -> 1 | H10: =COUNTIFS(data_entry[الشهر],H4,data_entry[التغذية الراجعة],"تم التغذية الراجعة") -> 1 | I10: =COUNTIFS(data_entry[الشهر],I4,data_entry[التغذية الراجعة],"تم التغذية الراجعة") -> 0 | ... M10: =COUNTIFS(data_entry[الشهر],M4,data_entry[التغذية الراجعة],"تم التغذية الراجعة") -> 0
A11: اجمالي الوقت المستغرق لحل الشكاوى | B11: =SUMIFS(data_entry[زمن الحل(يوم)],data_entry[الشهر],B4,data_entry[شهر الحل],B4) -> 0 | C11: =SUMIFS(data_entry[زمن الحل(يوم)],data_entry[الشهر],C4,data_entry[شهر الحل],C4) -> 0 | D11: =SUMIFS(data_entry[زمن الحل(يوم)],data_entry[الشهر],D4,data_entry[شهر الحل],D4) -> 0 | E11: =SUMIFS(data_entry[زمن الحل(يوم)],data_entry[الشهر],E4,data_entry[شهر الحل],E4) -> 0 | F11: =SUMIFS(data_entry[زمن الحل(يوم)],data_entry[الشهر],F4,data_entry[شهر الحل],F4) -> 0 | G11: =SUMIFS(data_entry[زمن الحل(يوم)],data_entry[الشهر],G4,data_entry[شهر الحل],G4) -> 5 | H11: =SUMIFS(data_entry[زمن الحل(يوم)],data_entry[الشهر],H4,data_entry[شهر الحل],H4) -> 0 | I11: =SUMIFS(data_entry[زمن الحل(يوم)],data_entry[الشهر],I4,data_entry[شهر الحل],I4) -> 0 | ... M11: =SUMIFS(data_entry[زمن الحل(يوم)],data_entry[الشهر],M4,data_entry[شهر الحل],M4) -> 0
A12: 📋 تصنيف الشكاوى
A13: الاغذية والمطبخ | B13: =COUNTIFS(data_entry[الشهر],B4,data_entry[نوع الشكوي],$A13) -> 0 | C13: =COUNTIFS(data_entry[الشهر],C4,data_entry[نوع الشكوي],$A13) -> 0 | D13: =COUNTIFS(data_entry[الشهر],D4,data_entry[نوع الشكوي],$A13) -> 0 | E13: =COUNTIFS(data_entry[الشهر],E4,data_entry[نوع الشكوي],$A13) -> 0 | F13: =COUNTIFS(data_entry[الشهر],F4,data_entry[نوع الشكوي],$A13) -> 0 | G13: =COUNTIFS(data_entry[الشهر],G4,data_entry[نوع الشكوي],$A13) -> 0 | H13: =COUNTIFS(data_entry[الشهر],H4,data_entry[نوع الشكوي],$A13) -> 0 | I13: =COUNTIFS(data_entry[الشهر],I4,data_entry[نوع الشكوي],$A13) -> 0 | ... M13: =COUNTIFS(data_entry[الشهر],M4,data_entry[نوع الشكوي],$A13) -> 0
A14: إدارية | B14: =COUNTIFS(data_entry[الشهر],B4,data_entry[نوع الشكوي],$A14) -> 0 | C14: =COUNTIFS(data_entry[الشهر],C4,data_entry[نوع الشكوي],$A14) -> 0 | D14: =COUNTIFS(data_entry[الشهر],D4,data_entry[نوع الشكوي],$A14) -> 0 | E14: =COUNTIFS(data_entry[الشهر],E4,data_entry[نوع الشكوي],$A14) -> 0 | F14: =COUNTIFS(data_entry[الشهر],F4,data_entry[نوع الشكوي],$A14) -> 0 | G14: =COUNTIFS(data_entry[الشهر],G4,data_entry[نوع الشكوي],$A14) -> 0 | H14: =COUNTIFS(data_entry[الشهر],H4,data_entry[نوع الشكوي],$A14) -> 0 | I14: =COUNTIFS(data_entry[الشهر],I4,data_entry[نوع الشكوي],$A14) -> 0 | ... M14: =COUNTIFS(data_entry[الشهر],M4,data_entry[نوع الشكوي],$A14) -> 0
A15: إجراءات الدخول | B15: =COUNTIFS(data_entry[الشهر],B4,data_entry[نوع الشكوي],$A15) -> 0 | C15: =COUNTIFS(data_entry[الشهر],C4,data_entry[نوع الشكوي],$A15) -> 0 | D15: =COUNTIFS(data_entry[الشهر],D4,data_entry[نوع الشكوي],$A15) -> 0 | E15: =COUNTIFS(data_entry[الشهر],E4,data_entry[نوع الشكوي],$A15) -> 0 | F15: =COUNTIFS(data_entry[الشهر],F4,data_entry[نوع الشكوي],$A15) -> 0 | G15: =COUNTIFS(data_entry[الشهر],G4,data_entry[نوع الشكوي],$A15) -> 0 | H15: =COUNTIFS(data_entry[الشهر],H4,data_entry[نوع الشكوي],$A15) -> 0 | I15: =COUNTIFS(data_entry[الشهر],I4,data_entry[نوع الشكوي],$A15) -> 0 | ... M15: =COUNTIFS(data_entry[الشهر],M4,data_entry[نوع الشكوي],$A15) -> 0
A16: توافر الأدوية | B16: =COUNTIFS(data_entry[الشهر],B4,data_entry[نوع الشكوي],$A16) -> 0 | C16: =COUNTIFS(data_entry[الشهر],C4,data_entry[نوع الشكوي],$A16) -> 0 | D16: =COUNTIFS(data_entry[الشهر],D4,data_entry[نوع الشكوي],$A16) -> 0 | E16: =COUNTIFS(data_entry[الشهر],E4,data_entry[نوع الشكوي],$A16) -> 0 | F16: =COUNTIFS(data_entry[الشهر],F4,data_entry[نوع الشكوي],$A16) -> 0 | G16: =COUNTIFS(data_entry[الشهر],G4,data_entry[نوع الشكوي],$A16) -> 1 | H16: =COUNTIFS(data_entry[الشهر],H4,data_entry[نوع الشكوي],$A16) -> 0 | I16: =COUNTIFS(data_entry[الشهر],I4,data_entry[نوع الشكوي],$A16) -> 0 | ... M16: =COUNTIFS(data_entry[الشهر],M4,data_entry[نوع الشكوي],$A16) -> 0
A17: معاملة الفريق الطبي | B17: =COUNTIFS(data_entry[الشهر],B4,data_entry[نوع الشكوي],$A17) -> 0 | C17: =COUNTIFS(data_entry[الشهر],C4,data_entry[نوع الشكوي],$A17) -> 0 | D17: =COUNTIFS(data_entry[الشهر],D4,data_entry[نوع الشكوي],$A17) -> 0 | E17: =COUNTIFS(data_entry[الشهر],E4,data_entry[نوع الشكوي],$A17) -> 0 | F17: =COUNTIFS(data_entry[الشهر],F4,data_entry[نوع الشكوي],$A17) -> 0 | G17: =COUNTIFS(data_entry[الشهر],G4,data_entry[نوع الشكوي],$A17) -> 0 | H17: =COUNTIFS(data_entry[الشهر],H4,data_entry[نوع الشكوي],$A17) -> 1 | I17: =COUNTIFS(data_entry[الشهر],I4,data_entry[نوع الشكوي],$A17) -> 0 | ... M17: =COUNTIFS(data_entry[الشهر],M4,data_entry[نوع الشكوي],$A17) -> 0
A18: وقت الانتظار | B18: =COUNTIFS(data_entry[الشهر],B4,data_entry[نوع الشكوي],$A18) -> 0 | C18: =COUNTIFS(data_entry[الشهر],C4,data_entry[نوع الشكوي],$A18) -> 0 | D18: =COUNTIFS(data_entry[الشهر],D4,data_entry[نوع الشكوي],$A18) -> 0 | E18: =COUNTIFS(data_entry[الشهر],E4,data_entry[نوع الشكوي],$A18) -> 0 | F18: =COUNTIFS(data_entry[الشهر],F4,data_entry[نوع الشكوي],$A18) -> 0 | G18: =COUNTIFS(data_entry[الشهر],G4,data_entry[نوع الشكوي],$A18) -> 1 | H18: =COUNTIFS(data_entry[الشهر],H4,data_entry[نوع الشكوي],$A18) -> 0 | I18: =COUNTIFS(data_entry[الشهر],I4,data_entry[نوع الشكوي],$A18) -> 0 | ... M18: =COUNTIFS(data_entry[الشهر],M4,data_entry[نوع الشكوي],$A18) -> 0
A19: اسعار الخدمات | B19: =COUNTIFS(data_entry[الشهر],B4,data_entry[نوع الشكوي],$A19) -> 0 | C19: =COUNTIFS(data_entry[الشهر],C4,data_entry[نوع الشكوي],$A19) -> 0 | D19: =COUNTIFS(data_entry[الشهر],D4,data_entry[نوع الشكوي],$A19) -> 0 | E19: =COUNTIFS(data_entry[الشهر],E4,data_entry[نوع الشكوي],$A19) -> 0 | F19: =COUNTIFS(data_entry[الشهر],F4,data_entry[نوع الشكوي],$A19) -> 0 | G19: =COUNTIFS(data_entry[الشهر],G4,data_entry[نوع الشكوي],$A19) -> 0 | H19: =COUNTIFS(data_entry[الشهر],H4,data_entry[نوع الشكوي],$A19) -> 0 | I19: =COUNTIFS(data_entry[الشهر],I4,data_entry[نوع الشكوي],$A19) -> 0 | ... M19: =COUNTIFS(data_entry[الشهر],M4,data_entry[نوع الشكوي],$A19) -> 0
A20: حقوق المرضى | B20: =COUNTIFS(data_entry[الشهر],B4,data_entry[نوع الشكوي],$A20) -> 0 | C20: =COUNTIFS(data_entry[الشهر],C4,data_entry[نوع الشكوي],$A20) -> 0 | D20: =COUNTIFS(data_entry[الشهر],D4,data_entry[نوع الشكوي],$A20) -> 0 | E20: =COUNTIFS(data_entry[الشهر],E4,data_entry[نوع الشكوي],$A20) -> 0 | F20: =COUNTIFS(data_entry[الشهر],F4,data_entry[نوع الشكوي],$A20) -> 0 | G20: =COUNTIFS(data_entry[الشهر],G4,data_entry[نوع الشكوي],$A20) -> 0 | H20: =COUNTIFS(data_entry[الشهر],H4,data_entry[نوع الشكوي],$A20) -> 0 | I20: =COUNTIFS(data_entry[الشهر],I4,data_entry[نوع الشكوي],$A20) -> 0 | ... M20: =COUNTIFS(data_entry[الشهر],M4,data_entry[نوع الشكوي],$A20) -> 0
A21: الأمن والنظافة | B21: =COUNTIFS(data_entry[الشهر],B4,data_entry[نوع الشكوي],$A21) -> 0 | C21: =COUNTIFS(data_entry[الشهر],C4,data_entry[نوع الشكوي],$A21) -> 0 | D21: =COUNTIFS(data_entry[الشهر],D4,data_entry[نوع الشكوي],$A21) -> 0 | E21: =COUNTIFS(data_entry[الشهر],E4,data_entry[نوع الشكوي],$A21) -> 0 | F21: =COUNTIFS(data_entry[الشهر],F4,data_entry[نوع الشكوي],$A21) -> 0 | G21: =COUNTIFS(data_entry[الشهر],G4,data_entry[نوع الشكوي],$A21) -> 0 | H21: =COUNTIFS(data_entry[الشهر],H4,data_entry[نوع الشكوي],$A21) -> 0 | I21: =COUNTIFS(data_entry[الشهر],I4,data_entry[نوع الشكوي],$A21) -> 0 | ... M21: =COUNTIFS(data_entry[الشهر],M4,data_entry[نوع الشكوي],$A21) -> 0
A22: التحويل والاحالة | B22: =COUNTIFS(data_entry[الشهر],B4,data_entry[نوع الشكوي],$A22) -> 0 | C22: =COUNTIFS(data_entry[الشهر],C4,data_entry[نوع الشكوي],$A22) -> 0 | D22: =COUNTIFS(data_entry[الشهر],D4,data_entry[نوع الشكوي],$A22) -> 0 | E22: =COUNTIFS(data_entry[الشهر],E4,data_entry[نوع الشكوي],$A22) -> 0 | F22: =COUNTIFS(data_entry[الشهر],F4,data_entry[نوع الشكوي],$A22) -> 0 | G22: =COUNTIFS(data_entry[الشهر],G4,data_entry[نوع الشكوي],$A22) -> 0 | H22: =COUNTIFS(data_entry[الشهر],H4,data_entry[نوع الشكوي],$A22) -> 0 | I22: =COUNTIFS(data_entry[الشهر],I4,data_entry[نوع الشكوي],$A22) -> 0 | ... M22: =COUNTIFS(data_entry[الشهر],M4,data_entry[نوع الشكوي],$A22) -> 0
A23: الفحوصات الطبية(اشعة/ معمل) | B23: =COUNTIFS(data_entry[الشهر],B4,data_entry[نوع الشكوي],$A23) -> 0 | C23: =COUNTIFS(data_entry[الشهر],C4,data_entry[نوع الشكوي],$A23) -> 0 | D23: =COUNTIFS(data_entry[الشهر],D4,data_entry[نوع الشكوي],$A23) -> 0 | E23: =COUNTIFS(data_entry[الشهر],E4,data_entry[نوع الشكوي],$A23) -> 0 | F23: =COUNTIFS(data_entry[الشهر],F4,data_entry[نوع الشكوي],$A23) -> 0 | G23: =COUNTIFS(data_entry[الشهر],G4,data_entry[نوع الشكوي],$A23) -> 0 | H23: =COUNTIFS(data_entry[الشهر],H4,data_entry[نوع الشكوي],$A23) -> 0 | I23: =COUNTIFS(data_entry[الشهر],I4,data_entry[نوع الشكوي],$A23) -> 0 | ... M23: =COUNTIFS(data_entry[الشهر],M4,data_entry[نوع الشكوي],$A23) -> 0
A24: عدم توافر الخدمة | B24: =COUNTIFS(data_entry[الشهر],B4,data_entry[نوع الشكوي],$A24) -> 0 | C24: =COUNTIFS(data_entry[الشهر],C4,data_entry[نوع الشكوي],$A24) -> 0 | D24: =COUNTIFS(data_entry[الشهر],D4,data_entry[نوع الشكوي],$A24) -> 0 | E24: =COUNTIFS(data_entry[الشهر],E4,data_entry[نوع الشكوي],$A24) -> 0 | F24: =COUNTIFS(data_entry[الشهر],F4,data_entry[نوع الشكوي],$A24) -> 0 | G24: =COUNTIFS(data_entry[الشهر],G4,data_entry[نوع الشكوي],$A24) -> 0 | H24: =COUNTIFS(data_entry[الشهر],H4,data_entry[نوع الشكوي],$A24) -> 0 | I24: =COUNTIFS(data_entry[الشهر],I4,data_entry[نوع الشكوي],$A24) -> 0 | ... M24: =COUNTIFS(data_entry[الشهر],M4,data_entry[نوع الشكوي],$A24) -> 0
A25: الاعطال و الصيانة | B25: =COUNTIFS(data_entry[الشهر],B4,data_entry[نوع الشكوي],$A25) -> 0 | C25: =COUNTIFS(data_entry[الشهر],C4,data_entry[نوع الشكوي],$A25) -> 0 | D25: =COUNTIFS(data_entry[الشهر],D4,data_entry[نوع الشكوي],$A25) -> 0 | E25: =COUNTIFS(data_entry[الشهر],E4,data_entry[نوع الشكوي],$A25) -> 0 | F25: =COUNTIFS(data_entry[الشهر],F4,data_entry[نوع الشكوي],$A25) -> 0 | G25: =COUNTIFS(data_entry[الشهر],G4,data_entry[نوع الشكوي],$A25) -> 0 | H25: =COUNTIFS(data_entry[الشهر],H4,data_entry[نوع الشكوي],$A25) -> 0 | I25: =COUNTIFS(data_entry[الشهر],I4,data_entry[نوع الشكوي],$A25) -> 0 | ... M25: =COUNTIFS(data_entry[الشهر],M4,data_entry[نوع الشكوي],$A25) -> 0
A26: أخرى | B26: =COUNTIFS(data_entry[الشهر],B4,data_entry[نوع الشكوي],$A26) -> 0 | C26: =COUNTIFS(data_entry[الشهر],C4,data_entry[نوع الشكوي],$A26) -> 0 | D26: =COUNTIFS(data_entry[الشهر],D4,data_entry[نوع الشكوي],$A26) -> 0 | E26: =COUNTIFS(data_entry[الشهر],E4,data_entry[نوع الشكوي],$A26) -> 0 | F26: =COUNTIFS(data_entry[الشهر],F4,data_entry[نوع الشكوي],$A26) -> 0 | G26: =COUNTIFS(data_entry[الشهر],G4,data_entry[نوع الشكوي],$A26) -> 0 | H26: =COUNTIFS(data_entry[الشهر],H4,data_entry[نوع الشكوي],$A26) -> 0 | I26: =COUNTIFS(data_entry[الشهر],I4,data_entry[نوع الشكوي],$A26) -> 0 | ... M26: =COUNTIFS(data_entry[الشهر],M4,data_entry[نوع الشكوي],$A26) -> 0
A28: 🎓 التدريب
A29: اجمالي عدد الاطباء بالوحدة | B29: =تدريب!C4 -> 12 | E29: =تدريب!F4 -> 12 | H29: =تدريب!I4 -> 0 | K29: =تدريب!L4 -> 0
A30: اجمالي عدد التمريض بالوحدة | B30: =تدريب!C5 -> 20 | E30: =تدريب!F5 -> 25 | H30: =تدريب!I5 -> 0 | K30: =تدريب!L5 -> 0
A31: اجمالي عدد العاملين الصحيين | B31: =B29+B30 -> 32 | E31: =E29+E30 -> 37 | H31: =H29+H30 -> 0 | K31: =K29+K30 -> 0
A32: اجمالي عدد العاملين | B32: =تدريب!C6 -> 60 | E32: =تدريب!F6 -> 65 | H32: =تدريب!I6 -> 0 | K32: =تدريب!L6 -> 0
A33: عدد الاطباء المدربين على BLS | B33: =تدريب!C7 -> 6 | E33: =تدريب!F7 -> 6 | H33: =تدريب!I7 -> 0 | K33: =تدريب!L7 -> 0
A34: عدد اعضاء هيئة التمريض المدربين على BLS | B34: =تدريب!C8 -> 15 | E34: =تدريب!F8 -> 15 | H34: =تدريب!I8 -> 0 | K34: =تدريب!L8 -> 0
A35: عدد العاملين المدربين على الدفاع المدني (شهادات معتمدة) | B35: =تدريب!C9 -> 12 | E35: =تدريب!F9 -> 12 | H35: =تدريب!I9 -> 0 | K35: =تدريب!L9 -> 0
A37: ❤️ الإفاقة القلبية التنفسية
A38: إجمالي عدد مرات الإفاقة القلبية التنفسية | B38: =COUNTIFS('الإفاقة القلبية'!$O:$O, TEXT(B4,"mmm-yyyy")) -> 0 | C38: =COUNTIFS('الإفاقة القلبية'!$O:$O, TEXT(C4,"mmm-yyyy")) -> 0 | D38: =COUNTIFS('الإفاقة القلبية'!$O:$O, TEXT(D4,"mmm-yyyy")) -> 0 | E38: =COUNTIFS('الإفاقة القلبية'!$O:$O, TEXT(E4,"mmm-yyyy")) -> 0 | F38: =COUNTIFS('الإفاقة القلبية'!$O:$O, TEXT(F4,"mmm-yyyy")) -> 0 | G38: =COUNTIFS('الإفاقة القلبية'!$O:$O, TEXT(G4,"mmm-yyyy")) -> 2 | H38: =COUNTIFS('الإفاقة القلبية'!$O:$O, TEXT(H4,"mmm-yyyy")) -> 0 | I38: =COUNTIFS('الإفاقة القلبية'!$O:$O, TEXT(I4,"mmm-yyyy")) -> 0 | ... M38: =COUNTIFS('الإفاقة القلبية'!$O:$O, TEXT(M4,"mmm-yyyy")) -> 0
A39: إجمالي عدد حالات النجاة بعد الإفاقة القلبية التنفسية | B39: =COUNTIFS('الإفاقة القلبية'!$O:$O, TEXT(B4,"mmm-yyyy"), 'الإفاقة القلبية'!$M:$M, "نجاة") -> 0 | C39: =COUNTIFS('الإفاقة القلبية'!$O:$O, TEXT(C4,"mmm-yyyy"), 'الإفاقة القلبية'!$M:$M, "نجاة") -> 0 | D39: =COUNTIFS('الإفاقة القلبية'!$O:$O, TEXT(D4,"mmm-yyyy"), 'الإفاقة القلبية'!$M:$M, "نجاة") -> 0 | E39: =COUNTIFS('الإفاقة القلبية'!$O:$O, TEXT(E4,"mmm-yyyy"), 'الإفاقة القلبية'!$M:$M, "نجاة") -> 0 | F39: =COUNTIFS('الإفاقة القلبية'!$O:$O, TEXT(F4,"mmm-yyyy"), 'الإفاقة القلبية'!$M:$M, "نجاة") -> 0 | G39: =COUNTIFS('الإفاقة القلبية'!$O:$O, TEXT(G4,"mmm-yyyy"), 'الإفاقة القلبية'!$M:$M, "نجاة") -> 0 | H39: =COUNTIFS('الإفاقة القلبية'!$O:$O, TEXT(H4,"mmm-yyyy"), 'الإفاقة القلبية'!$M:$M, "نجاة") -> 0 | I39: =COUNTIFS('الإفاقة القلبية'!$O:$O, TEXT(I4,"mmm-yyyy"), 'الإفاقة القلبية'!$M:$M, "نجاة") -> 0 | ... M39: =COUNTIFS('الإفاقة القلبية'!$O:$O, TEXT(M4,"mmm-yyyy"), 'الإفاقة القلبية'!$M:$M, "نجاة") -> 0
A40: إجمالي عدد حالات الوفاة بعد الإفاقة القلبية التنفسية | B40: =COUNTIFS('الإفاقة القلبية'!$O:$O, TEXT(B4,"mmm-yyyy"), 'الإفاقة القلبية'!$M:$M, "وفاة") -> 0 | C40: =COUNTIFS('الإفاقة القلبية'!$O:$O, TEXT(C4,"mmm-yyyy"), 'الإفاقة القلبية'!$M:$M, "وفاة") -> 0 | D40: =COUNTIFS('الإفاقة القلبية'!$O:$O, TEXT(D4,"mmm-yyyy"), 'الإفاقة القلبية'!$M:$M, "وفاة") -> 0 | E40: =COUNTIFS('الإفاقة القلبية'!$O:$O, TEXT(E4,"mmm-yyyy"), 'الإفاقة القلبية'!$M:$M, "وفاة") -> 0 | F40: =COUNTIFS('الإفاقة القلبية'!$O:$O, TEXT(F4,"mmm-yyyy"), 'الإفاقة القلبية'!$M:$M, "وفاة") -> 0 | G40: =COUNTIFS('الإفاقة القلبية'!$O:$O, TEXT(G4,"mmm-yyyy"), 'الإفاقة القلبية'!$M:$M, "وفاة") -> 1 | H40: =COUNTIFS('الإفاقة القلبية'!$O:$O, TEXT(H4,"mmm-yyyy"), 'الإفاقة القلبية'!$M:$M, "وفاة") -> 0 | I40: =COUNTIFS('الإفاقة القلبية'!$O:$O, TEXT(I4,"mmm-yyyy"), 'الإفاقة القلبية'!$M:$M, "وفاة") -> 0 | ... M40: =COUNTIFS('الإفاقة القلبية'!$O:$O, TEXT(M4,"mmm-yyyy"), 'الإفاقة القلبية'!$M:$M, "وفاة") -> 0
A41: إجمالي عدد حالات الوفاة خلال 24 ساعة من الإفاقة القلبية التنفسية | B41: NA | C41: NA | D41: NA | E41: NA | F41: NA | G41: NA | H41: NA | I41: NA | J41: NA | K41: NA | L41: NA | M41: NA
A42: إجمالي عدد حالات الوفاة بعد 24 ساعة من الإفاقة القلبية التنفسية | B42: NA | C42: NA | D42: NA | E42: NA | F42: NA | G42: NA | H42: NA | I42: NA | J42: NA | K42: NA | L42: NA | M42: NA
A43: عدد مرات تفعيل الكود بلو | B43: =COUNTIFS('الإفاقة القلبية'!$O:$O, TEXT(B$4,"mmm-yyyy"), 'الإفاقة القلبية'!$I:$I, ">0") -> 0 | C43: =COUNTIFS('الإفاقة القلبية'!$O:$O, TEXT(C$4,"mmm-yyyy"), 'الإفاقة القلبية'!$I:$I, ">0") -> 0 | D43: =COUNTIFS('الإفاقة القلبية'!$O:$O, TEXT(D$4,"mmm-yyyy"), 'الإفاقة القلبية'!$I:$I, ">0") -> 0 | E43: =COUNTIFS('الإفاقة القلبية'!$O:$O, TEXT(E$4,"mmm-yyyy"), 'الإفاقة القلبية'!$I:$I, ">0") -> 0 | F43: =COUNTIFS('الإفاقة القلبية'!$O:$O, TEXT(F$4,"mmm-yyyy"), 'الإفاقة القلبية'!$I:$I, ">0") -> 0 | G43: =COUNTIFS('الإفاقة القلبية'!$O:$O, TEXT(G$4,"mmm-yyyy"), 'الإفاقة القلبية'!$I:$I, ">0") -> 2 | H43: =COUNTIFS('الإفاقة القلبية'!$O:$O, TEXT(H$4,"mmm-yyyy"), 'الإفاقة القلبية'!$I:$I, ">0") -> 0 | I43: =COUNTIFS('الإفاقة القلبية'!$O:$O, TEXT(I$4,"mmm-yyyy"), 'الإفاقة القلبية'!$I:$I, ">0") -> 0 | ... M43: =COUNTIFS('الإفاقة القلبية'!$O:$O, TEXT(M$4,"mmm-yyyy"), 'الإفاقة القلبية'!$I:$I, ">0") -> 0
...

Sheet نتائج المؤشرات الشهرية
A1: 📊 نتائج المؤشرات الشهرية
A3: م | B3: كود المؤشر | C3: المؤشر | D3: Jan-26 | E3: Feb-26 | F3: Mar-26 | G3: Apr-26 | H3: May-26 | I3: Jun-26 | J3: Jul-26 | K3: Aug-26 | L3: Sep-26 | M3: Oct-26 | N3: Nov-26 | O3: Dec-26
A4: مؤشرات تردد العيادات
A5: 1 | B5: FU-004 | C5: اجمالي تردد العيادات الخارجية | D5: =SUM(D6:D12) -> 0 | E5: =SUM(E6:E12) -> 0 | F5: =SUM(F6:F12) -> 0 | G5: =SUM(G6:G12) -> 0 | H5: =SUM(H6:H12) -> 0 | I5: =SUM(I6:I12) -> 785 | J5: =SUM(J6:J12) -> 0 | K5: =SUM(K6:K12) -> 0 | ... O5: =SUM(O6:O12) -> 0
